<mujoco model="turtlebot3_manipulation_ui">
  <compiler angle="radian" autolimits="true"/>
  <option timestep="0.002" gravity="0 0 -9.81"/>
  <statistic center="-0.02 0 0.24" extent="0.55"/>

  <visual>
    <global azimuth="140" elevation="-25"/>
    <headlight diffuse="0.6 0.6 0.6" ambient="0.25 0.25 0.25" specular="0.1 0.1 0.1"/>
  </visual>

  <asset>
    <material name="floor_mat" rgba="0.18 0.19 0.20 1"/>
    <material name="dark_mat" rgba="0.2 0.2 0.2 1"/>
    <material name="base_mat" rgba="0.4 0.4 0.4 1"/>
    <material name="camera_mat" rgba="0.6 0.6 0.6 1"/>
    <material name="eef_camera_mat" rgba="0.08 0.08 0.08 1"/>
    <material name="tower_mat" rgba="0.32 0.36 0.40 1"/>
    <material name="object_mat" rgba="0.9 0.25 0.08 1"/>
    <mesh name="link2" file="meshes/open_manipulator_x/link2.stl" scale="0.001 0.001 0.001"/>
    <mesh name="link3" file="meshes/open_manipulator_x/link3.stl" scale="0.001 0.001 0.001"/>
    <mesh name="link4" file="meshes/open_manipulator_x/link4.stl" scale="0.001 0.001 0.001"/>
    <mesh name="link5" file="meshes/open_manipulator_x/link5.stl" scale="0.001 0.001 0.001"/>
    <mesh name="gripper_left_palm" file="meshes/open_manipulator_x/gripper_left_palm.stl" scale="0.001 0.001 0.001"/>
    <mesh name="gripper_right_palm" file="meshes/open_manipulator_x/gripper_right_palm.stl" scale="0.001 0.001 0.001"/>
  </asset>

  <worldbody>
    <light name="key_light" pos="0.6 -0.8 1.2" dir="-0.6 0.8 -1" diffuse="0.8 0.8 0.75"/>
    <geom name="floor" type="plane" size="1.2 1.2 0.02" pos="0 0 0" material="floor_mat" contype="0" conaffinity="0"/>
    <geom name="task_tower" type="box" size="0.065 0.065 0.085" pos="0.27 0 0.085" material="tower_mat" condim="4" friction="1 0.1 0.1"/>
    <body name="reach_target_body" mocap="true" pos="0.27 0 0.1975">
      <site name="reach_target" type="sphere" size="0.015" rgba="0 0 0 0"/>
    </body>
    <body name="grasp_object_body" mocap="true" pos="0.27 0 0.1975">
      <geom name="grasp_object" type="box" size="0.03 0.0275 0.0275" material="object_mat" condim="4" friction="1 0.1 0.1"/>
      <site name="grasp_object_site" type="sphere" size="0.006" rgba="0 0 0 0"/>
    </body>
    <site name="handoff_place_site" pos="0.27 0 0.1975" type="sphere" size="0.018" rgba="0 0 0 0"/>

    <geom name="base" size="0.133 0.133 0.047" pos="-0.064 0 0.063" type="box" material="base_mat"/>
    <geom name="caster_back_right" size="0.014 0.0045 0.01" pos="-0.177 -0.0639992 0.011" quat="0.707388 -0.706825 0 0" type="box"/>
    <geom name="caster_back_left" size="0.014 0.0045 0.01" pos="-0.177 0.0640008 0.011" quat="0.707388 -0.706825 0 0" type="box"/>
    <geom name="camera_plate" size="0.133 0.133 0.0025" pos="-0.064 0 0.131" type="box" material="dark_mat"/>
    <geom name="camera_body" size="0.02 0.0825 0.015" pos="0.0475 0 0.1675" type="box" material="camera_mat"/>
    <geom name="camera_mount" size="0.03 0.03 0.0095" pos="0.0385 0 0.143" type="box" material="camera_mat"/>
    <geom name="support_front_left" size="0.005 0.0275" pos="0.043 0.05 0.161" type="cylinder" material="dark_mat"/>
    <geom name="support_front_right" size="0.005 0.0275" pos="0.043 -0.05 0.161" type="cylinder" material="dark_mat"/>
    <geom name="support_back_left" size="0.005 0.0275" pos="-0.182 0.05 0.161" type="cylinder" material="dark_mat"/>
    <geom name="support_back_right" size="0.005 0.0275" pos="-0.182 -0.05 0.161" type="cylinder" material="dark_mat"/>
    <geom name="upper_waffle_plate" size="0.145 0.068 0.005" pos="-0.092 0 0.1935" type="box" material="dark_mat"/>
    <geom name="link1_collision" size="0.025 0.025 0.025" pos="-0.092 0 0.194" type="box"/>

    <body name="wheel_left_link" pos="0 0.144 0.039" quat="0.707388 -0.706825 0 0">
      <inertial pos="0 0 0" quat="-0.000890159 0.706886 0.000889646 0.707326" mass="0.0284989" diaginertia="2.07126e-05 1.11924e-05 1.11756e-05"/>
      <joint name="wheel_left_joint" pos="0 0 0" axis="0 0 1" damping="0.1"/>
      <geom name="wheel_left" size="0.033 0.009" type="cylinder" material="dark_mat"/>
    </body>
    <body name="wheel_right_link" pos="0 -0.144 0.039" quat="0.707388 -0.706825 0 0">
      <inertial pos="0 0 0" quat="-0.000890159 0.706886 0.000889646 0.707326" mass="0.0284989" diaginertia="2.07126e-05 1.11924e-05 1.11756e-05"/>
      <joint name="wheel_right_joint" pos="0 0 0" axis="0 0 1" damping="0.1"/>
      <geom name="wheel_right" size="0.033 0.009" type="cylinder" material="dark_mat"/>
    </body>

    <body name="link2" pos="-0.08 0 0.211">
      <inertial pos="-0.000301849 0.000540437 0.0474335" quat="0.999915 0.000960074 0.0122201 -0.00449872" mass="0.0984068" diaginertia="3.4553e-05 3.26892e-05 1.88409e-05"/>
      <joint name="joint1" pos="0 0 0" axis="0 0 1" range="-2.82743 2.82743" actuatorfrcrange="-4 4" damping="0.35" armature="0.002"/>
      <geom name="link2_mesh" pos="0 0 0.019" type="mesh" mesh="link2"/>
      <body name="link3" pos="0 0 0.0595">
        <inertial pos="0.0103084 0.000377434 0.101702" quat="0.71133 0.0466763 0.0513691 0.699423" mass="0.138509" diaginertia="0.000342915 0.000335932 5.49578e-05"/>
        <joint name="joint2" pos="0 0 0" axis="0 1 0" range="-1.79071 1.5708" actuatorfrcrange="-4 4" damping="0.45" armature="0.003"/>
        <geom name="link3_mesh" type="mesh" mesh="link3"/>
        <body name="link4" pos="0.024 0 0.128">
          <inertial pos="0.0909096 0.000389298 0.000224133" quat="-0.00162881 0.706672 0.0026348 0.707535" mass="0.132746" diaginertia="0.000251551 0.000242311 3.06462e-05"/>
          <joint name="joint3" pos="0 0 0" axis="0 1 0" range="-0.942478 1.3823" actuatorfrcrange="-4 4" damping="0.45" armature="0.003"/>
          <geom name="link4_mesh" type="mesh" mesh="link4"/>
          <body name="link5" pos="0.124 0 0">
            <inertial pos="0.0442068 3.684e-07 0.00891422" quat="0.479052 0.479052 -0.520105 0.520105" mass="0.143276" diaginertia="9.3211e-05 8.07871e-05 7.59805e-05"/>
            <joint name="joint4" pos="0 0 0" axis="0 1 0" range="-1.79071 2.04204" actuatorfrcrange="-4 4" damping="0.35" armature="0.002"/>
            <geom name="link5_mesh" type="mesh" mesh="link5"/>
            <site name="end_effector" pos="0.126 0 0" size="0.008" rgba="0 0 0 0"/>
            <body name="eef_usb_camera_link" pos="0.02 0 0.065">
              <geom name="eef_usb_camera_body" pos="0.025 0 0" type="box" size="0.025 0.045 0.0225" material="eef_camera_mat" contype="0" conaffinity="0"/>
              <geom name="eef_usb_camera_lens" pos="0.052 0 0" quat="0.707107 0 0.707107 0" type="cylinder" size="0.012 0.004" rgba="0.02 0.02 0.02 1" contype="0" conaffinity="0"/>
              <site name="eef_usb_camera_optical_frame" pos="0 0 0" euler="-1.57079632679 0 -1.57079632679" size="0.006" rgba="0 0 0 0"/>
              <camera name="eef_usb_camera" pos="0 0 0" euler="-1.57079632679 0 -1.57079632679" fovy="60"/>
            </body>
            <body name="gripper_left_link" pos="0.0817 0.021 0">
              <inertial pos="0 0 0" mass="0.001" diaginertia="1e-06 1e-06 1e-06"/>
              <joint name="gripper_left_joint" pos="0 0 0" axis="0 1 0" type="slide" range="-0.01 0.019" actuatorfrcrange="-1 1" damping="0.15"/>
              <geom name="gripper_left_mesh" type="mesh" mesh="gripper_left_palm"/>
            </body>
            <body name="gripper_right_link" pos="0.0817 -0.021 0">
              <inertial pos="0 0 0" mass="0.001" diaginertia="1e-06 1e-06 1e-06"/>
              <joint name="gripper_right_joint" pos="0 0 0" axis="0 -1 0" type="slide" range="-0.01 0.019" actuatorfrcrange="-1 1" damping="0.15"/>
              <geom name="gripper_right_mesh" type="mesh" mesh="gripper_right_palm"/>
            </body>
          </body>
        </body>
      </body>
    </body>
  </worldbody>

  <equality>
    <joint name="gripper_mimic" joint1="gripper_right_joint" joint2="gripper_left_joint" polycoef="0 1 0 0 0"/>
  </equality>

  <actuator>
    <!-- ctrl values are absolute joint-position targets, matching the MuJoCo viewer sliders. -->
    <general name="joint1_position" joint="joint1" gaintype="fixed" gainprm="220" biastype="affine" biasprm="0 -220 0" ctrlrange="-2.82743 2.82743" forcerange="-4 4"/>
    <general name="joint2_position" joint="joint2" gaintype="fixed" gainprm="220" biastype="affine" biasprm="0 -220 0" ctrlrange="-1.79071 1.5708" forcerange="-4 4"/>
    <general name="joint3_position" joint="joint3" gaintype="fixed" gainprm="180" biastype="affine" biasprm="0 -180 0" ctrlrange="-0.942478 1.3823" forcerange="-4 4"/>
    <general name="joint4_position" joint="joint4" gaintype="fixed" gainprm="180" biastype="affine" biasprm="0 -180 0" ctrlrange="-1.79071 2.04204" forcerange="-4 4"/>
    <general name="gripper_position" joint="gripper_left_joint" gaintype="fixed" gainprm="450" biastype="affine" biasprm="0 -450 0" ctrlrange="-0.01 0.019" forcerange="-2 2"/>
  </actuator>

  <keyframe>
    <key name="stay" qpos="0 0 0.104311 0.027612 -0.001534 -1.638291 0 0" ctrl="0.104311 0.027612 -0.001534 -1.638291 0"/>
    <key name="moveit_home" qpos="0 0 0 -1 0.7 0.3 0.01 0.01" ctrl="0 -1 0.7 0.3 0.01"/>
  </keyframe>
</mujoco>
